Workbook

Sheet Summary
A1: Decision Platform — 30/60/90 delivery backlog
A2: Aligned to the executive deck, slide 14. Each horizon is defined by the outcome that becomes true at the end of it.
A3: Generated 24 September 2026. Story points are planning estimates, not commitments — see the capacity note below.
A5: HORIZON | B5: SUCCESS CRITERION | C5: EPICS | D5: ISSUES | E5: POINTS | F5: CRITICAL PTS
A6: By Day 30 | B6: We can reconstruct every eligible decision and its counterfactual. | C6: =COUNTIFS(Backlog!$L:$L,"D30",Backlog!$B:$B,"Epic") -> 4 | D6: =COUNTIFS(Backlog!$L:$L,"D30")-C6 -> 26 | E6: =SUMIFS(Backlog!$H:$H,Backlog!$L:$L,"D30") -> 115 | F6: =SUMIFS(Backlog!$H:$H,Backlog!$L:$L,"D30",Backlog!$I:$I,"Y") -> 102
A7: By Day 60 | B7: We can register, replay and validate a strategy without a release. | C7: =COUNTIFS(Backlog!$L:$L,"D60",Backlog!$B:$B,"Epic") -> 5 | D7: =COUNTIFS(Backlog!$L:$L,"D60")-C7 -> 28 | E7: =SUMIFS(Backlog!$H:$H,Backlog!$L:$L,"D60") -> 189 | F7: =SUMIFS(Backlog!$H:$H,Backlog!$L:$L,"D60",Backlog!$I:$I,"Y") -> 164
A8: By Day 90 | B8: We have one controlled experiment running and can produce an economic readout. | C8: =COUNTIFS(Backlog!$L:$L,"D90",Backlog!$B:$B,"Epic") -> 6 | D8: =COUNTIFS(Backlog!$L:$L,"D90")-C8 -> 35 | E8: =SUMIFS(Backlog!$H:$H,Backlog!$L:$L,"D90") -> 249 | F8: =SUMIFS(Backlog!$H:$H,Backlog!$L:$L,"D90",Backlog!$I:$I,"Y") -> 221
A9: Beyond Day 90 | B9: Scale to more decision points, open Experiment 2, begin learned strategies. | C9: =COUNTIFS(Backlog!$L:$L,"D90+",Backlog!$B:$B,"Epic") -> 1 | D9: =COUNTIFS(Backlog!$L:$L,"D90+")-C9 -> 4 | E9: =SUMIFS(Backlog!$H:$H,Backlog!$L:$L,"D90+") -> 34 | F9: =SUMIFS(Backlog!$H:$H,Backlog!$L:$L,"D90+",Backlog!$I:$I,"Y") -> 34
A10: TOTAL | C10: =SUM(C6:C9) -> 16 | D10: =SUM(D6:D9) -> 93 | E10: =SUM(E6:E9) -> 587 | F10: =SUM(F6:F9) -> 521
A13: CAPACITY CHECK — does the plan fit?
A14: Edit the blue cells. Everything else is a formula.
A15: Sprint length (weeks) | B15: 2
A16: Sprints in 90 days | B16: 6
A17: Velocity per squad per sprint (points) | B17: 30
A18: Points one squad delivers in 90 days | B18: =B16*B17 -> 180
A19: Points required for D30 + D60 + D90 (all) | B19: =E6+E7+E8 -> 553
A20: Points required for D30 + D60 + D90 (critical only) | B20: =F6+F7+F8 -> 487
A21: Squads needed — full scope | B21: =ROUND(B19/B18,1) -> 3.1
A22: Squads needed — critical scope only | B22: =ROUND(B20/B18,1) -> 2.7
A24: The deck says the mechanism is buildable inside existing platform capacity. That is true of the mechanism, not of this schedule. If only one squad is available, the 90-day outcomes need either more time or a scope cut against the Critical To Outcome column.

Sheet Backlog
A1: # | B1: Issue Type | C1: Epic | D1: Summary | E1: Description | F1: Acceptance Criteria | G1: Priority | H1: Story Points | I1: Critical To Outcome | J1: Requirement | K1: Objective | L1: Fix Version | M1: Component | N1: Team | O1: Blocked By
A2: 1 | B2: Epic | C2: Decision Evidence Layer | D2: Decision Evidence Layer | E2: Every eligible decision on the CURRENT engine emits what was chosen, what else was permitted, the probability assigned, and what the fallback would have done. This is the one capability that cannot be backfilled. | G2: P0 | J2: R8 | K2: O3 | L2: D30 | M2: Decision Runtime | N2: Payments Platform
A3: 2 | B3: Story | C3: Decision Evidence Layer | D3: Define the decision record schema | E3: As the platform, I need a single schema for every decision the engine makes, so that decisions from different decision points are comparable and joinable. | F3: • Schema covers: decision point id, strategy id and version, chosen action, permitted action set, propensity assigned to the chosen action, fallback action that would have fired, population context, timestamp, transaction and customer identifiers. • Schema is versioned and additive-only. • Reviewed and signed off by Architecture and Analytics Engineering. | G3: P0 | H3: 5 | I3: Y | J3: R8 | K3: O3 | L3: D30 | M3: Decision Runtime | N3: Payments Platform
A4: 3 | B4: Story | C4: Decision Evidence Layer | D4: Emit decision records from the routing engine (D6) | E4: As an analyst, I need every routing decision logged with its counterfactual, so that routing strategies can later be evaluated off-policy. | F4: • Every D6 decision on eligible traffic emits a record. • No change to the routing decision itself — output is byte-identical to today for a control sample of 1M transactions. • Record includes the permitted processor set and the fallback processor. | G4: P0 | H4: 8 | I4: Y | J4: R8 | K4: O3 | L4: D30 | M4: Decision Runtime | N4: Payments Platform | O4: Define the decision record schema
A5: 4 | B5: Story | C5: Decision Evidence Layer | D5: Emit decision records from the retry engine (D4.2) | E5: As an analyst, I need retry decisions logged with what else was permitted, so that retry strategies become evaluable. | F5: • Every D4.2 decision emits a record, including no-action decisions. • Retry behaviour unchanged. • Retry records link to the parent authorization attempt. | G5: P0 | H5: 8 | I5: Y | J5: R8 | K5: O3 | L5: D30 | M5: Decision Runtime | N5: Payments Platform | O5: Define the decision record schema
A6: 5 | B6: Story | C6: Decision Evidence Layer | D6: Emit decision records from credential selection (D4.1) | E6: As an analyst, I need credential selection logged with the alternative credential, so that Experiment 1 has a counterfactual to report. | F6: • Every D4.1 decision emits a record naming the credential presented and the credential not presented. • Credential values are tokenised in the record — no PAN in the event store. • Credential selection behaviour unchanged. | G6: P0 | H6: 8 | I6: Y | J6: R8 | K6: O3 | L6: D30 | M6: Decision Runtime | N6: Payments Platform | O6: Define the decision record schema
A7: 6 | B7: Story | C7: Decision Evidence Layer | D7: Assign and document propensity for deterministic strategies | E7: As an analyst, I need a stated propensity convention for deterministic strategies, so that off-policy estimators are not silently mis-specified later. | F7: • Deterministic strategies record propensity 1.0 on the chosen action and 0 on the alternatives. • Convention is documented alongside the schema, with the implications for off-policy evaluation stated. • A strategy class field distinguishes DETERMINISTIC from future stochastic classes. | G7: P0 | H7: 3 | I7: Y | J7: R8 | K7: O3 | L7: D30 | M7: Decision Runtime | N7: Payments Platform | O7: Define the decision record schema
A8: 7 | B8: Story | C8: Decision Evidence Layer | D8: Record the fallback action without executing it | E8: As the platform, I need to know what the fallback would have done, so that attribution is possible without running two flows. | F8: • Fallback resolution runs in shadow and never dispatches. • Added latency measured and within the agreed budget. • Fallback field is never null for a decision that has a registered fallback. | G8: P0 | H8: 5 | I8: Y | J8: R8 | K8: O3 | L8: D30 | M8: Decision Runtime | N8: Payments Platform | O8: Define the decision record schema
A9: 8 | B9: Story | C9: Decision Evidence Layer | D9: Persist decision records with 13-month retention | E9: As an analyst, I need at least four quarters of history, so that seasonality can be separated from effect. | F9: • Records land in the event store within 60 seconds of the decision. • 13-month retention configured and cost-modelled. • Partitioned for efficient replay by date range and decision point. | G9: P0 | H9: 5 | I9: Y | J9: R8 | K9: O3 | L9: D30 | M9: Decision Runtime | N9: Payments Platform | O9: Define the decision record schema
A10: 9 | B10: Story | C10: Decision Evidence Layer | D10: Block synthesised propensity in downstream jobs | E10: As a reviewer, I need the platform to refuse reconstructed propensity, so that an evaluated result is never quietly based on a guess. | F10: • Any job writing a propensity value for a record that did not carry one is rejected. • Rejection is logged and alerts the strategy owner. • Documented as a platform invariant, not a lint rule. | G10: P0 | H10: 3 | I10: N | J10: R8 | K10: O3 | L10: D30 | M10: Decision Runtime | N10: Payments Platform | O10: Persist decision records with 13-month retention
A11: 10 | B11: Story | C11: Decision Evidence Layer | D11: Verify record completeness against transaction volume | E11: As a reviewer, I need proof that the evidence layer is not silently dropping decisions, so that a later readout is trustworthy. | F11: • Daily reconciliation: decision records vs eligible transactions, by decision point. • Completeness at or above 99.5%. • Shortfall below threshold raises an alert with the missing population identified. | G11: P0 | H11: 5 | I11: Y | J11: R8 | K11: O3 | L11: D30 | M11: Decision Runtime | N11: Payments Platform | O11: Persist decision records with 13-month retention
A12: 11 | B12: Spike | C12: Decision Evidence Layer | D12: SPIKE: measure added latency of decision-record emission | E12: As the platform owner, I need to know what the evidence layer costs in latency before it goes to full traffic, so that the authorization path is not degraded. | F12: • p50, p95 and p99 added latency measured at production-representative volume. • Result compared against the agreed latency budget. • Recommendation on synchronous vs asynchronous emission, with the trade-off on completeness stated. | G12: P0 | H12: 3 | I12: Y | J12: R8 | K12: O3 | L12: D30 | M12: Decision Runtime | N12: Payments Platform
A13: 12 | B13: Epic | C13: Permanent Platform Holdout | D13: Permanent Platform Holdout | E13: A 2% population reserved before the first experiment runs, excluded from experiments and from exploration, with a creation date that cannot be edited. | G13: P0 | J13: R7 | K13: O2 O3 | L13: D30 | M13: Decision Runtime | N13: Payments Platform
A14: 13 | B14: Story | C14: Permanent Platform Holdout | D14: Define holdout eligibility and the assignment rule | E14: As the platform owner, I need a stated rule for who is in the holdout, so that it is defensible and stable over time. | F14: • Eligibility defined at customer level, with the population and exclusions written down. • Assignment is a deterministic hash — same customer, same answer, forever. • Rule reviewed by Analytics Engineering for representativeness against the total population. | G14: P0 | H14: 3 | I14: Y | J14: R7 | K14: O2 O3 | L14: D30 | M14: Decision Runtime | N14: Payments Platform
A15: 14 | B15: Story | C15: Permanent Platform Holdout | D15: Implement deterministic 2% holdout assignment | E15: As the platform, I need holdout membership computed the same way everywhere, so that it cannot drift between services. | F15: • Assignment implemented once and consumed by every caller. • Same customer resolves identically across regions. • Membership resolvable in under 1ms. | G15: P0 | H15: 5 | I15: Y | J15: R7 | K15: O2 O3 | L15: D30 | M15: Decision Runtime | N15: Payments Platform | O15: Define holdout eligibility and the assignment rule
A16: 15 | B16: Story | C16: Permanent Platform Holdout | D16: Exclude the holdout from experiments and from exploration | E16: As a reviewer, I need the holdout untouched by any learning activity, so that it measures the platform rather than the experiments. | F16: • Holdout members are never enrolled in any experiment. • Holdout members are never selected for exploration traffic. • An attempt to include them fails closed and raises an alert. | G16: P0 | H16: 5 | I16: Y | J16: R7 | K16: O2 O3 | L16: D30 | M16: Decision Runtime | N16: Payments Platform | O16: Implement deterministic 2% holdout assignment
A17: 16 | B17: Story | C17: Permanent Platform Holdout | D17: Persist holdout membership with an immutable creation date | E17: As a reviewer, I need to prove when the holdout was reserved, so that the claim that it pre-dates the experiments is verifiable. | F17: • Creation date recorded at first assignment and not editable by any role. • Membership history retained for the life of the platform. • Audit log for any membership change. | G17: P0 | H17: 3 | I17: Y | J17: R7 | K17: O2 O3 | L17: D30 | M17: Decision Runtime | N17: Payments Platform | O17: Implement deterministic 2% holdout assignment
A18: 17 | B18: Story | C18: Permanent Platform Holdout | D18: Holdout health report | E18: As an analyst, I need to see holdout composition and drift, so that a divergence from the general population is caught early. | F18: • Weekly report: volume, merchant mix, geography mix, card mix vs the non-holdout population. • Alerts on material composition drift. • Report retained as evidence alongside readouts. | G18: P1 | H18: 5 | I18: N | J18: R7 | K18: O2 O3 | L18: D30 | M18: Decision Runtime | N18: Payments Platform | O18: Persist holdout membership with an immutable creation date
A19: 18 | B19: Story | C19: Permanent Platform Holdout | D19: Document the holdout as a governed, non-resizable asset | E19: As the platform owner, I need a stated rule that the holdout cannot be quietly resized, so that its value is not eroded under delivery pressure. | F19: • Written policy: resizing or reconstituting the holdout requires a named approval from the platform owner. • Policy referenced in the experiment registration gates. | G19: P1 | H19: 2 | I19: N | J19: R7 | K19: O2 O3 | L19: D30 | M19: Decision Runtime | N19: Payments Platform
A20: 19 | B20: Epic | C20: Decision-Point & Capability Registry — Definition | D20: Decision-Point & Capability Registry — Definition | E20: Agree what the decision points are, what each may choose from, and what a route can actually support. Scope and schema only — the build is D60. | G20: P0 | J20: R1 | K20: O1 O5 | L20: D30 | M20: Architecture | N20: Architecture
A21: 20 | B21: Story | C21: Decision-Point & Capability Registry — Definition | D21: Catalogue the current decision points and permitted action sets | E21: As an architect, I need a written inventory of where the payment flow makes choices, so that the registry describes reality rather than an ideal. | F21: • All five current decision points documented: D4 gate, D4.1 credential, D4.2 retry, D5 authentication, D6 routing. • Permitted action set enumerated for each, as implemented today. • Gaps between documented and actual behaviour listed explicitly. | G21: P0 | H21: 5 | I21: Y | J21: R1 | K21: O1 O5 | L21: D30 | M21: Architecture | N21: Architecture
A22: 21 | B22: Story | C22: Decision-Point & Capability Registry — Definition | D22: Define the capability model | E22: As an architect, I need a model of what each route and processor can actually support, so that a strategy cannot select an option that will fail downstream. | F22: • Capability dimensions defined: credential forms accepted, authentication methods, currencies, MCCs, network tokens, retry semantics. • Model distinguishes contractual capability from technical capability. • Reviewed with Network and Processor Management. | G22: P0 | H22: 5 | I22: Y | J22: R1 | K22: O1 O5 | L22: D30 | M22: Architecture | N22: Architecture
A23: 22 | B23: Story | C23: Decision-Point & Capability Registry — Definition | D23: Agree the registry schema and versioning approach | E23: As an architect, I need the registry to be bitemporal, so that we can answer both what is true now and what was true when a decision was made. | F23: • Schema covers valid time and knowledge time. • Versioning and deprecation rules written down. • Signed off by Architecture. | G23: P0 | H23: 3 | I23: Y | J23: R1 | K23: O1 O5 | L23: D30 | M23: Architecture | N23: Architecture | O23: Catalogue the current decision points and permitted action sets
A24: 23 | B24: Spike | C24: Decision-Point & Capability Registry — Definition | D24: SPIKE: survey processor capability data availability | E24: As an architect, I need to know which capability facts we can obtain and which we will have to assert, so that the D60 verification work is correctly sized. | F24: • Each processor surveyed for available capability data and format. • Gaps listed with an estimate of effort to close. • Recommendation on which facts must be verified vs may be asserted with an expiry. | G24: P0 | H24: 5 | I24: Y | J24: R1 | K24: O1 O5 | L24: D30 | M24: Architecture | N24: Architecture | O24: Define the capability model
A25: 24 | B25: Story | C25: Decision-Point & Capability Registry — Definition | D25: Publish the registry scope decision for sign-off | E25: As the programme, I need the registry scope agreed before it is built, so that D60 is a build rather than a design. | F25: • Scope document published naming what is in and out of the first registry. • Architecture sign-off recorded. • Out-of-scope items carried to the D90+ backlog rather than dropped. | G25: P0 | H25: 2 | I25: Y | J25: R1 | K25: O1 O5 | L25: D30 | M25: Architecture | N25: Architecture | O25: Agree the registry schema and versioning approach
A26: 25 | B26: Epic | C26: Operating Model & Ownership | D26: Operating Model & Ownership | E26: The five ownership boundaries named, the exploration budget bounded, the economic objective expressed in a usable form, and the consent posture settled. | G26: P0 | J26: — | K26: O1 O4 | L26: D30 | M26: Governance | N26: Product
A27: 26 | B27: Story | C27: Operating Model & Ownership | D27: Assign and document the five ownership boundaries | E27: As the programme, I need named owners for the five decisions that bound the platform, so that they are not re-litigated every quarter. | F27: • Named owner recorded for: economic objective, exploration budget, decision-point registry, exposure authority, exploration consent. • Each owner has confirmed in writing. • Escalation path defined where two owners disagree. | G27: P0 | H27: 3 | I27: Y | J27: — | K27: O1 O4 | L27: D30 | M27: Governance | N27: Product
A28: 27 | B28: Story | C28: Operating Model & Ownership | D28: Define the exploration budget in basis points, with a ceiling | E28: As Product, I need a stated budget for what learning costs, so that exploration is a decision rather than an accident. | F28: • Budget expressed in bps of qualifying volume, per quarter. • Hard ceiling defined, above which an experiment cannot start. • Consumption tracked and reported against the budget. | G28: P0 | H28: 3 | I28: Y | J28: — | K28: O1 O4 | L28: D30 | M28: Governance | N28: Product | O28: Assign and document the five ownership boundaries
A29: 28 | B29: Story | C29: Operating Model & Ownership | D29: Define the economic objective form by pricing model | E29: As Product and Finance, I need the approval-versus-cost trade-off expressed in a form a strategy can actually consume, so that BALANCED is a real posture rather than a label. | F29: • Objective expressed as an exchange rate: bps of cost accepted per 100 bps of approval. • A value agreed separately for interchange-plus and for blended pricing. • Documented with worked examples in both directions. | G29: P0 | H29: 5 | I29: Y | J29: — | K29: O1 O4 | L29: D30 | M29: Governance | N29: Product | O29: Assign and document the five ownership boundaries
A30: 29 | B30: Story | C30: Operating Model & Ownership | D30: Legal review of exploration consent posture | E30: As the programme, I need to know whether a knowingly weaker arm on a named client needs contractual consent, so that Experiment 1 does not stop at the last gate. | F30: • Legal opinion recorded on running a deliberately degraded arm on live merchant traffic. • Position stated for existing contracts and for new ones. • If consent is required, the consent artefact and the signing path are defined. | G30: P0 | H30: 5 | I30: Y | J30: — | K30: O1 O4 | L30: D30 | M30: Governance | N30: Product | O30: Assign and document the five ownership boundaries
A31: 30 | B31: Story | C31: Operating Model & Ownership | D31: Define the experiment review forum and decision rights | E31: As the programme, I need a standing forum with stated decision rights, so that promotion and abort decisions are made rather than escalated. | F31: • Forum membership, cadence and quorum defined. • Decision rights stated: who may promote, who may abort, who may widen exposure. • First meeting scheduled. | G31: P1 | H31: 3 | I31: N | J31: — | K31: O1 O4 | L31: D30 | M31: Governance | N31: Product | O31: Assign and document the five ownership boundaries
A32: 31 | B32: Epic | C32: Strategy Registry & Artefact Lifecycle | D32: Strategy Registry & Artefact Lifecycle | E32: A strategy becomes a registered, versioned artefact with an owner, a fallback and an expiry — deployable without an engineering release. | G32: P0 | J32: R1 R14 | K32: O1 O4 | L32: D60 | M32: Control Plane | N32: Payments Platform
A33: 32 | B33: Story | C33: Strategy Registry & Artefact Lifecycle | D33: Strategy artefact schema | E33: As a strategy owner, I need a strategy to be a declared artefact rather than code, so that it can be reviewed, versioned and retired without a release. | F33: • Schema: id, version, decision point, class, population predicate, definition, fallback strategy reference, owner, expiry. • Fallback is mandatory and must reference a registered strategy. • Owner and expiry are mandatory. | G33: P0 | H33: 5 | I33: Y | J33: R1 R14 | K33: O1 O4 | L33: D60 | M33: Control Plane | N33: Payments Platform | O33: Agree the registry schema and versioning approach
A34: 33 | B34: Story | C34: Strategy Registry & Artefact Lifecycle | D34: Strategy registration API and CLI | E34: As a strategy owner, I need to register a strategy without an engineering release, so that the change cycle is days rather than quarters. | F34: • API accepts a strategy artefact and returns a registered version. • CLI wraps the API for the common path. • Registration is rejected with a specific, actionable message when a field is invalid. | G34: P0 | H34: 8 | I34: Y | J34: R1 | K34: O1 O4 | L34: D60 | M34: Control Plane | N34: Payments Platform | O34: Strategy artefact schema
A35: 34 | B35: Story | C35: Strategy Registry & Artefact Lifecycle | D35: Version immutability | E35: As a reviewer, I need a registered version to be unchangeable, so that a readout always refers to a known artefact. | F35: • A registered version cannot be edited — a change produces a new version. • Prior versions remain resolvable indefinitely. • Attempted edit is rejected and audited. | G35: P0 | H35: 5 | I35: Y | J35: R1 | K35: O1 O4 | L35: D60 | M35: Control Plane | N35: Payments Platform | O35: Strategy registration API and CLI
A36: 35 | B36: Story | C36: Strategy Registry & Artefact Lifecycle | D36: Owner and expiry enforcement | E36: As the platform owner, I need strategies to expire, so that nothing lingers unowned in the decision path. | F36: • Expiry is mandatory at registration, with a maximum of 180 days. • Warnings to the owner at 30 and 7 days. • An expired strategy stops being bindable; flows already bound to it fall back and alert. | G36: P0 | H36: 5 | I36: Y | J36: R14 | K36: O1 O4 | L36: D60 | M36: Control Plane | N36: Payments Platform | O36: Strategy registration API and CLI
A37: 36 | B37: Story | C37: Strategy Registry & Artefact Lifecycle | D37: Strategy retirement workflow | E37: As a strategy owner, I need a clean way to retire a strategy, so that losing variants do not accumulate. | F37: • Retirement blocks new bindings and reports which flows still reference the strategy. • Retirement is reversible within 30 days, then permanent. • Retired strategies remain resolvable for historical traces. | G37: P1 | H37: 5 | I37: N | J37: R14 | K37: O1 O4 | L37: D60 | M37: Control Plane | N37: Payments Platform | O37: Version immutability
A38: 37 | B38: Story | C38: Strategy Registry & Artefact Lifecycle | D38: Naming convention validation | E38: As a reviewer, I need strategy names to describe what they do, so that a trace is readable a year later. | F38: • Registration rejects opaque names such as Strategy1 or Test_A. • Convention documented with positive and negative examples. • Existing names migrated before D60 exit. | G38: P2 | H38: 2 | I38: N | J38: R1 | K38: O1 O4 | L38: D60 | M38: Control Plane | N38: Payments Platform | O38: Strategy registration API and CLI
A39: 38 | B39: Epic | C39: Flow Composition & Single-Difference Compiler | D39: Flow Composition & Single-Difference Compiler | E39: A flow binds exactly one strategy at every decision point, and the compiler refuses to build a variant that differs from its baseline at more than one. | G39: P0 | J39: R2 | K39: O2 | L39: D60 | M39: Control Plane | N39: Payments Platform
A40: 39 | B40: Story | C40: Flow Composition & Single-Difference Compiler | D40: Flow artefact schema | E40: As a strategy owner, I need a flow to name exactly one strategy at every decision point, so that there is no implicit behaviour in the path. | F40: • Schema: flow id, version, baseline reference, one binding per decision point. • An unbound decision point is a compile error, never a default. • Baseline reference is mandatory for a variant flow. | G40: P0 | H40: 5 | I40: Y | J40: R2 | K40: O2 | L40: D60 | M40: Control Plane | N40: Payments Platform | O40: Strategy artefact schema
...

Sheet Epics
A1: Epic Key | B1: Epic Name | C1: Horizon | D1: Objective | E1: Requirement | F1: Component | G1: Owning Team | H1: Stories | I1: Points | J1: Critical Pts | K1: Epic Goal
A2: DP-1 | B2: Decision Evidence Layer | C2: D30 | D2: O3 | E2: R8 | F2: Decision Runtime | G2: Payments Platform | H2: =COUNTIFS(Backlog!$C:$C,$B2,Backlog!$B:$B,"<>Epic") -> 10 | I2: =SUMIFS(Backlog!$H:$H,Backlog!$C:$C,$B2) -> 53 | J2: =SUMIFS(Backlog!$H:$H,Backlog!$C:$C,$B2,Backlog!$I:$I,"Y") -> 50 | K2: Every eligible decision on the CURRENT engine emits what was chosen, what else was permitted, the probability assigned, and what the fallback would have done. This is the one capability that cannot be backfilled.
A3: DP-2 | B3: Permanent Platform Holdout | C3: D30 | D3: O2 O3 | E3: R7 | F3: Decision Runtime | G3: Payments Platform | H3: =COUNTIFS(Backlog!$C:$C,$B3,Backlog!$B:$B,"<>Epic") -> 6 | I3: =SUMIFS(Backlog!$H:$H,Backlog!$C:$C,$B3) -> 23 | J3: =SUMIFS(Backlog!$H:$H,Backlog!$C:$C,$B3,Backlog!$I:$I,"Y") -> 16 | K3: A 2% population reserved before the first experiment runs, excluded from experiments and from exploration, with a creation date that cannot be edited.
A4: DP-3 | B4: Decision-Point & Capability Registry — Definition | C4: D30 | D4: O1 O5 | E4: R1 | F4: Architecture | G4: Architecture | H4: =COUNTIFS(Backlog!$C:$C,$B4,Backlog!$B:$B,"<>Epic") -> 5 | I4: =SUMIFS(Backlog!$H:$H,Backlog!$C:$C,$B4) -> 20 | J4: =SUMIFS(Backlog!$H:$H,Backlog!$C:$C,$B4,Backlog!$I:$I,"Y") -> 20 | K4: Agree what the decision points are, what each may choose from, and what a route can actually support. Scope and schema only — the build is D60.
A5: DP-4 | B5: Operating Model & Ownership | C5: D30 | D5: O1 O4 | E5: — | F5: Governance | G5: Product | H5: =COUNTIFS(Backlog!$C:$C,$B5,Backlog!$B:$B,"<>Epic") -> 5 | I5: =SUMIFS(Backlog!$H:$H,Backlog!$C:$C,$B5) -> 19 | J5: =SUMIFS(Backlog!$H:$H,Backlog!$C:$C,$B5,Backlog!$I:$I,"Y") -> 16 | K5: The five ownership boundaries named, the exploration budget bounded, the economic objective expressed in a usable form, and the consent posture settled.
A6: DP-5 | B6: Strategy Registry & Artefact Lifecycle | C6: D60 | D6: O1 O4 | E6: R1 R14 | F6: Control Plane | G6: Payments Platform | H6: =COUNTIFS(Backlog!$C:$C,$B6,Backlog!$B:$B,"<>Epic") -> 6 | I6: =SUMIFS(Backlog!$H:$H,Backlog!$C:$C,$B6) -> 30 | J6: =SUMIFS(Backlog!$H:$H,Backlog!$C:$C,$B6,Backlog!$I:$I,"Y") -> 23 | K6: A strategy becomes a registered, versioned artefact with an owner, a fallback and an expiry — deployable without an engineering release.
A7: DP-6 | B7: Flow Composition & Single-Difference Compiler | C7: D60 | D7: O2 | E7: R2 | F7: Control Plane | G7: Payments Platform | H7: =COUNTIFS(Backlog!$C:$C,$B7,Backlog!$B:$B,"<>Epic") -> 6 | I7: =SUMIFS(Backlog!$H:$H,Backlog!$C:$C,$B7) -> 47 | J7: =SUMIFS(Backlog!$H:$H,Backlog!$C:$C,$B7,Backlog!$I:$I,"Y") -> 42 | K7: A flow binds exactly one strategy at every decision point, and the compiler refuses to build a variant that differs from its baseline at more than one.
A8: DP-7 | B8: Replay & Backtest | C8: D60 | D8: O1 O4 | E8: R3 | F8: Decision Runtime | G8: Payments Platform | H8: =COUNTIFS(Backlog!$C:$C,$B8,Backlog!$B:$B,"<>Epic") -> 5 | I8: =SUMIFS(Backlog!$H:$H,Backlog!$C:$C,$B8) -> 33 | J8: =SUMIFS(Backlog!$H:$H,Backlog!$C:$C,$B8,Backlog!$I:$I,"Y") -> 33 | K8: A candidate flow runs against logged decision records and produces an exact count of decisions that would change, and for whom, before any live exposure.
A9: DP-8 | B9: Experiment Registration & Mechanical Gates | C9: D60 | D9: O2 | E9: R5 | F9: Control Plane | G9: Experimentation | H9: =COUNTIFS(Backlog!$C:$C,$B9,Backlog!$B:$B,"<>Epic") -> 7 | I9: =SUMIFS(Backlog!$H:$H,Backlog!$C:$C,$B9) -> 42 | J9: =SUMIFS(Backlog!$H:$H,Backlog!$C:$C,$B9,Backlog!$I:$I,"Y") -> 42 | K9: Registration pre-declares hypothesis, metric, effect size, direction, population, weights and stopping rule — and the gates that catch a broken design are mechanical, not a reviewer.
A10: DP-9 | B10: Registry Build & Processor Verification | C10: D60 | D10: O5 | E10: R1 | F10: Architecture | G10: Architecture | H10: =COUNTIFS(Backlog!$C:$C,$B10,Backlog!$B:$B,"<>Epic") -> 4 | I10: =SUMIFS(Backlog!$H:$H,Backlog!$C:$C,$B10) -> 37 | J10: =SUMIFS(Backlog!$H:$H,Backlog!$C:$C,$B10,Backlog!$I:$I,"Y") -> 24 | K10: The decision-point and capability registries built and verified with processors rather than asserted, and enforced as a capability filter at decision time.
A11: DP-10 | B11: Assignment & Exposure Control | C11: D90 | D11: O2 O4 | E11: R4 R6 | F11: Decision Runtime | G11: Payments Platform | H11: =COUNTIFS(Backlog!$C:$C,$B11,Backlog!$B:$B,"<>Epic") -> 6 | I11: =SUMIFS(Backlog!$H:$H,Backlog!$C:$C,$B11) -> 47 | J11: =SUMIFS(Backlog!$H:$H,Backlog!$C:$C,$B11,Backlog!$I:$I,"Y") -> 42 | K11: Promotion is decoupled from exposure, assignment is deterministic at the divergence point, and traffic moves by changing a number rather than by a deployment.
A12: DP-11 | B12: Live Monitoring & Automatic Guardrail Abort | C12: D90 | D12: O4 | E12: R9 | F12: Observability | G12: Experimentation | H12: =COUNTIFS(Backlog!$C:$C,$B12,Backlog!$B:$B,"<>Epic") -> 6 | I12: =SUMIFS(Backlog!$H:$H,Backlog!$C:$C,$B12) -> 52 | J12: =SUMIFS(Backlog!$H:$H,Backlog!$C:$C,$B12,Backlog!$I:$I,"Y") -> 47 | K12: Exposure, pace and guardrails visible in real time, with an arm removed from allocation automatically within one propagation cycle on breach.
A13: DP-12 | B13: Decision Trace | C13: D90 | D13: O5 | E13: R10 | F13: Observability | G13: Experimentation | H13: =COUNTIFS(Backlog!$C:$C,$B13,Backlog!$B:$B,"<>Epic") -> 5 | I13: =SUMIFS(Backlog!$H:$H,Backlog!$C:$C,$B13) -> 39 | J13: =SUMIFS(Backlog!$H:$H,Backlog!$C:$C,$B13,Backlog!$I:$I,"Y") -> 26 | K13: Any transaction explained end to end — experiment membership, arm, flow, every decision applied and what the baseline would have decided — self-serve, in under two minutes.
... A17: DP-16 | B17: Credential Seasoning (enables Experiment 2) | C17: D90+ | D17: O2 | E17: R15 | F17: Credential Vault | G17: Credential Vault | H17: =COUNTIFS(Backlog!$C:$C,$B17,Backlog!$B:$B,"<>Epic") -> 4 | I17: =SUMIFS(Backlog!$H:$H,Backlog!$C:$C,$B17) -> 34 | J17: =SUMIFS(Backlog!$H:$H,Backlog!$C:$C,$B17,Backlog!$I:$I,"Y") -> 34 | K17: Provisioning decoupled from presentation so a treatment seasons before exposure — without this, Experiment 2 measures a freshly minted token rather than the vault.

Sheet Risks & Dependencies
A1: ID | B1: Type | C1: Risk | D1: Detail | E1: Status | F1: Owner
A2: R-1 | B2: Capacity | C2: The 90-day plan is not fundable from a single squad | D2: D30 to D90 totals well above what two squads deliver in six sprints. Either resource to three squads or cut scope against the Critical To Outcome column. | E2: Open | F2: Product · Platform
A3: R-2 | B3: Legal | C3: Exploration consent may block Experiment 1 at the last gate | D3: A knowingly weaker arm on a named client may require contractual consent that existing agreements do not cover. Consent work is on the D30 critical path for that reason. | E3: Open | F3: Legal · Client Service
A4: R-3 | B4: Methodology | C4: Assignment at the wrong point silently dilutes the result | D4: If assignment happens at context assembly rather than at the divergence point, transactions that could never receive the treatment enter the variant arm and depress the measured effect. DP-10 must land before any live exposure. | E4: Mitigated by DP-10 | F4: Payments Platform
A5: R-4 | B5: Methodology | C5: Token seasoning confounds Experiment 2 | D5: Provisioning only the variant cohort at experiment start measures new-token performance, not vault performance, and understates the vault. DP-16 must precede Experiment 2. | E5: Mitigated by DP-16 | F5: Credential Vault
A6: R-5 | B6: Data | C6: Decision-record completeness below 99.5% invalidates readouts | D6: A silent drop in emission biases the measured population. Reconciliation (DP-1) is a gate on every readout, not a nice-to-have. | E6: Mitigated by DP-1 | F6: Payments Platform
A7: R-6 | B7: Latency | C7: Evidence-layer emission adds latency to the authorization path | D7: Fallback shadow resolution and record emission both sit near the critical path. The SPIKE in DP-1 determines synchronous vs asynchronous, and that choice trades latency against completeness. | E7: Open | F7: Payments Platform
A8: R-7 | B8: Compliance | C8: Trace data may expand PCI scope | D8: Decision traces reference credential selection. Scope assessment is inside DP-12 and must complete before the trace UI is exposed beyond engineering. | E8: Open | F8: Compliance · Platform
A9: R-8 | B9: Commercial | C9: Blended-pricing merchants make the vault a cost to us | D9: If Experiment 1 confirms the exchange rate, the economics differ by pricing model and a pricing decision follows. This is an outcome of the plan, not a risk to it — but it needs an owner before the readout lands. | E9: Open | F9: Product · Finance
A10: R-9 | B10: Scope | C10: Registry verification with processors is externally dependent | D10: DP-9 processor verification depends on third-party responsiveness and cannot be compressed by adding people. Treat asserted-with-expiry as the fallback. | E10: Open | F10: Architecture
A11: R-10 | B11: Governance | C11: Holdout erosion under delivery pressure | D11: A 2% holdout is a standing temptation to reclaim. The non-resizable policy (DP-2) exists because this is the most likely quiet failure of the platform. | E11: Mitigated by DP-2 | F11: Product

Sheet Definition of Done
A1: Definition of Done — per horizon
A2: A horizon is complete when its criterion can be demonstrated, not when its stories are closed.
A4: By Day 30 | B4: We can reconstruct every eligible decision and its counterfactual.
B5: ☐ Pick any transaction from the last 30 days. Show what was chosen at D4.1, D4.2 and D6, what else was permitted, the propensity, and what the fallback would have done.
B6: ☐ Decision-record completeness is at or above 99.5% against eligible transaction volume, evidenced by the daily reconciliation.
B7: ☐ The 2% holdout exists, has an immutable creation date that pre-dates every experiment, and is excluded from both experiments and exploration.
B8: ☐ Five ownership boundaries have named owners who have confirmed in writing.
B9: ☐ The economic objective is expressed as an exchange rate, with a value for interchange-plus and a value for blended pricing.
B10: ☐ Registry scope is signed off by Architecture — not built, agreed.
A12: By Day 60 | B12: We can register, replay and validate a strategy without a release.
B13: ☐ Register a new strategy and compose a variant flow, end to end, with no engineering release and no deployment window.
B14: ☐ The compiler rejects a variant that differs from its baseline at two decision points, and the rejection names both points.
B15: ☐ Replay the candidate against 30 days of logged decisions and produce an exact changed-decision count with the affected population.
B16: ☐ Register an experiment and watch the mechanical gates reject a deliberately broken design — unreachable treatment, per-transaction randomisation, occupied allocation slot.
B17: ☐ The capability filter removes unsupported options before a strategy evaluates, and the decision record shows why.
B18: ☐ Nothing in this list required a human reviewer to catch a design error.
A20: By Day 90 | B20: We have one controlled experiment running and can produce an economic readout.
B21: ☐ Experiment 1 is live, assignment happens at the divergence point, and treatment fidelity is above the declared floor.
B22: ☐ Exposure moves by changing a number; a rehearsed rollback completes within one propagation cycle.
B23: ☐ A guardrail breach removes an arm from allocation automatically, demonstrated in a game day.
B24: ☐ Any transaction can be explained end to end — membership, arm, flow, every decision, every counterfactual.
B25: ☐ A scorecard publishes with all six dimensions, confidence intervals and status. Approval alone cannot be published.
B26: ☐ The result is translated into merchant margin and PSP net revenue for both pricing models, with the exchange rate stated.
B27: ☐ The readout carries a measurement window, a baseline version and an expiry date.
B28: ☐ The review forum has recorded a promote, hold or retire decision against it.
